<?xml version="1.0" ?>
<robot xmlns:xacro="http://www.ros.org/wiki/xacro">


<xacro:macro name="gripper" params="prefix">


    <!-- Part 6 Gripper Base Joint -->
    <joint name="Part6_Gripper_Base" type="revolute">
        <parent link="link_6" />
        <child link="Gripper_Base" />
        <origin rpy="0 -1.57 0" xyz="0 0 0" />
        <axis xyz="0 0 1" />
        <dynamics damping="0.7" />
        <limit effort="100" lower="0" upper="0" velocity="100" />
    </joint>
    <!-- Gripper Base -->
    <link name="Gripper_Base">
        <collision>
            <origin rpy="-1.57 0 0" xyz="-0.065 -0.065 0" />
            <geometry>
                <mesh filename="package://fanuc_lrmate200id_support/meshes/gripper/collision/Gripper_base.STL" scale="0.001 0.001 0.001" />
            </geometry>
        </collision>
        <visual>
            <origin rpy="-1.57 0 0" xyz="-0.065 -0.065 0" />
            <geometry>
                <mesh filename="package://fanuc_lrmate200id_support/meshes/gripper/visual/Gripper_base.STL" scale="0.001 0.001 0.001" />
            </geometry>
            <material name="">
                <color rgba="0.96 0.76 0.13 1.0" />
            </material>
        </visual>
        
<inertial>
            <origin rpy="0 0 0" xyz="0.00112 0.04196 0" />
            <mass value="1.067" />
            <inertia ixx="0.00372062398" ixy="-0.000013337910" ixz="0.000000013" iyy=".00223540544" iyz="-0.00000003496" izz=".003641916" />
        </inertial>

    </link>
    <gazebo reference="Gripper_Base">
        <material>Gazebo/Black</material>
    </gazebo>
    <!-- Gripper Base Finger 3 Joint-->
    <joint name="Gripper_Finger3" type="revolute">
        <parent link="Gripper_Base" />
        <child link="Finger3" />
        <origin rpy="0 0 0" xyz="0.04448 0 -0.09533" />
        <axis xyz="0 1 0" />
        <dynamics damping="0.7" />
        <limit effort="1" lower="-0.4" upper="0.4" velocity="6.1087" />
    </joint>
    <!-- Finger 3-->
    <link name="Finger3">
        <collision>
            <origin rpy="-1.57 0 3.14" xyz="0.075 0.038 0.075" />
            <geometry>
                <mesh filename="package://fanuc_lrmate200id_support/meshes/gripper/collision/Gripper_finger.STL" scale="0.001 0.001 0.001" />
            </geometry>
        </collision>
        <visual>
            <origin rpy="-1.57 0 3.14" xyz="0.075 0.038 0.075" />
            <geometry>
                <mesh filename="package://fanuc_lrmate200id_support/meshes/gripper/visual/Gripper_finger.STL" scale="0.001 0.001 0.001" />
            </geometry>
            <material name="">
                <color rgba="0.278431372549 0.278431372549 0.278431372549 1.0" />
            </material>
        </visual>
        
<inertial>
            <origin rpy="0 0 0" xyz="0.00112 0.04196 0" />
            <mass value="0.17495" />
            <inertia ixx="0.002449587" ixy="-0.00141880714" ixz="-0.00044070839" iyy=".00018834795" iyz="-0.00067806067" izz=".00315304482" />
        </inertial>

    </link>
    <!-- Base Finger1 Joint -->
    <!-- Gripper Base Finger 1 Joint-->
    <joint name="Gripper_Finger1" type="revolute">
        <parent link="Gripper_Base" />
        <child link="Finger1" />
        <origin rpy="0 0 0" xyz="-0.04448 0.04 -0.09533" />
        <axis xyz="0 1 0" />
        <dynamics damping="0.7" />
        <limit effort="1" lower="-0.4" upper="0.4" velocity="6.1087" />
    </joint>
    <!-- Finger 1-->
    <link name="Finger1">
        <collision>
            <origin rpy="-1.57 0 0" xyz="-0.075 -0.038 0.075" />
            <geometry>
                <mesh filename="package://fanuc_lrmate200id_support/meshes/gripper/collision/Gripper_finger.STL" scale="0.001 0.001 0.001" />
            </geometry>
        </collision>
        <visual>
            <origin rpy="-1.57 0 0" xyz="-0.075 -0.038 0.075" />
            <geometry>
                <mesh filename="package://fanuc_lrmate200id_support/meshes/gripper/visual/Gripper_finger.STL" scale="0.001 0.001 0.001" />
            </geometry>
            <material name="">
                <color rgba="0.278431372549 0.278431372549 0.278431372549 1.0" />
            </material>
        </visual>
        
<inertial>
            <origin rpy="0 0 0" xyz="0.00112 0.04196 0" />
            <mass value="0.17495" />
            <inertia ixx="0.002449587" ixy="-0.00141880714" ixz="-0.00044070839" iyy=".00018834795" iyz="-0.00067806067" izz=".00315304482" />
        </inertial>

    </link>
    <!-- Gripper Base Finger 2 Joint-->
    <joint name="Gripper_Finger2" type="revolute">
        <parent link="Gripper_Base" />
        <child link="Finger2" />
        <origin rpy="0 0 0" xyz="-0.04448 -0.04 -0.09533" />
        <axis xyz="0 1 0" />
        <dynamics damping="0.7" />
        <limit effort="1" lower="-0.4" upper="0.4" velocity="6.1087" />
    </joint>
    <!-- Finger 2-->
    <link name="Finger2">
        <collision>
            <origin rpy="-1.57 0 0" xyz="-0.075 -0.038 0.075" />
            <geometry>
                <mesh filename="package://fanuc_lrmate200id_support/meshes/gripper/collision/Gripper_finger.STL" scale="0.001 0.001 0.001" />
            </geometry>
        </collision>
        <visual>
            <origin rpy="-1.57 0 0" xyz="-0.075 -0.038 0.075" />
            <geometry>
                <mesh filename="package://fanuc_lrmate200id_support/meshes/gripper/visual/Gripper_finger.STL" scale="0.001 0.001 0.001" />
            </geometry>
            <material name="">
                <color rgba="0.278431372549 0.278431372549 0.278431372549 1.0" />
            </material>
        </visual>
        
<inertial>
            <origin rpy="0 0 0" xyz="0.00112 0.04196 0" />
            <mass value="0.17495" />
            <inertia ixx="0.002449587" ixy="-0.00141880714" ixz="-0.00044070839" iyy=".00018834795" iyz="-0.00067806067" izz=".00315304482" />
        </inertial>

    </link>
    


    <transmission name="trans_Part6_Gripper_Base">
        <type>transmission_interface/SimpleTransmission</type>
        <joint name="Part6_Gripper_Base">
            <hardwareInterface>hardware_interface/EffortJointInterface</hardwareInterface>
        </joint>
        <actuator name="Part6_Gripper_Base_motor">
            <hardwareInterface>hardware_interface/EffortJointInterface</hardwareInterface>
            <mechanicalReduction>1</mechanicalReduction>
        </actuator>
    </transmission>
    <transmission name="trans_Gripper_Finger3">
        <type>transmission_interface/SimpleTransmission</type>
        <joint name="Gripper_Finger3">
            <hardwareInterface>hardware_interface/EffortJointInterface</hardwareInterface>
        </joint>
        <actuator name="Gripper_Finger3_motor">
            <hardwareInterface>hardware_interface/EffortJointInterface</hardwareInterface>
            <mechanicalReduction>1</mechanicalReduction>
        </actuator>
    </transmission>
    <transmission name="trans_Gripper_Finger1">
        <type>transmission_interface/SimpleTransmission</type>
        <joint name="Gripper_Finger1">
            <hardwareInterface>hardware_interface/EffortJointInterface</hardwareInterface>
        </joint>
        <actuator name="Gripper_Finger1_motor">
            <hardwareInterface>hardware_interface/EffortJointInterface</hardwareInterface>
            <mechanicalReduction>1</mechanicalReduction>
        </actuator>
    </transmission>
    <transmission name="trans_Gripper_Finger2">
        <type>transmission_interface/SimpleTransmission</type>
        <joint name="Gripper_Finger2">
            <hardwareInterface>hardware_interface/EffortJointInterface</hardwareInterface>
        </joint>
        <actuator name="Gripper_Finger2_motor">
            <hardwareInterface>hardware_interface/EffortJointInterface</hardwareInterface>
            <mechanicalReduction>1</mechanicalReduction>
        </actuator>
    </transmission>

	</xacro:macro>
</robot>