<?xml version = "1.0" ?>
<robot name = "fanuc_lrmate200id7l" xmlns:xacro="http://www.ros.org/wiki/xacro" >
<xacro:macro name="fanuc_lrmate200id7l" params="prefix">
<!--Gazebo ROS Control -->
<gazebo>
  <plugin name="gazebo_ros_control" filename="libgazebo_ros_control.so">
    <robotNamespace>/${prefix}</robotNamespace>
    <legacyModeNS>true</legacyModeNS>
  </plugin>
</gazebo>

<!--Base -->


<link name="${prefix}base_link">
	<collision>
		<geometry>
			<mesh filename = "package://fanuc_lrmate200id_support/meshes/lrmate200id/collision/base_link.stl"  />
		</geometry>
	<origin xyz = "0 0 0" rpy = "0 0 0"/>
	</collision>

	<visual>
 		<geometry>
			<mesh filename = "package://fanuc_lrmate200id_support/meshes/lrmate200id/visual/base_link.stl" />
		</geometry>
	<origin xyz = "0 0 0" rpy = "0 0 0"/>
	</visual>
	<inertial>
		<origin xyz = "0.0 0.0 0.0" rpy = "0 0 0" /> 
		<mass value = "6.215"/>
        <inertia ixx="0.0247272" ixy="-8.0784E-05" ixz="0.00130902" iyy="0.0491285" iyz="-8.0419E-06" izz="0.0472376"/>	</inertial>
</link>

<link name = "world"/>
  
<joint name="world_base_joint" type="fixed">
	<parent link="world"/>
	<child link="${prefix}base_link" />
	<origin xyz = "0.7 -1.6 0.7" rpy = "0 0 0"/>
</joint> 

<gazebo reference= "${prefix}base_link" >
	<material>Gazebo/Black</material>
</gazebo>

<joint name="${prefix}joint_1" type="revolute">
      <origin xyz="0 0 0.330" rpy="0 0 0" />
      <parent link="${prefix}base_link" />
      <child link="${prefix}link_1" />
      <axis xyz="0 0 1" />
      <limit effort="0" lower="-2.965" upper="2.965" velocity="7.85" />
      <dynamics damping="1.0" friction="5.0"/>

</joint>

 <link name ="${prefix}link_1">
	<collision>
	<geometry>
		<mesh filename= "package://fanuc_lrmate200id_support/meshes/lrmate200id/collision/link_1.stl"/>
	</geometry>
		<origin xyz="0 0 0" rpy ="0 0 0"/>
	</collision>
	<visual>
	<geometry>
		<mesh filename="package://fanuc_lrmate200id_support/meshes/lrmate200id/visual/link_1.stl"/>
	</geometry>
		<origin xyz="0 0 0" rpy="0 0 0"/>
	</visual>
	<inertial>
        <origin xyz="-0.000010 -0.054550 0.028725" rpy="0 0 0"/>
		<mass value = "1"/>
        <inertia
          ixx="${600 * 0.000048}" ixy="0.0" ixz="${600 * -0.000006}"
          iyy="${600 * 0.000035}" iyz="0.0" izz="${600 * 0.000037}"/>	</inertial>
</link>

<gazebo reference= "${prefix}link_1" >
	<material>Gazebo/Orange</material>
</gazebo>

<joint name="${prefix}joint_2" type="revolute">
      <origin xyz="0.050 0 0" rpy="0 0 0"/>
      <parent link="${prefix}link_1" />
      <child link="${prefix}link_2" />
      <axis xyz="0 1 0" />
      <limit effort="0" lower="-1.745329" upper="2.530727" velocity="6.63" />
      <dynamics damping="1.0" friction="5.0"/>

</joint>

<!--Part3-->
<link name = "${prefix}link_2">
	<collision>
		<origin xyz="0 0 0" rpy="0 0 0"/>
		<geometry>
			<mesh filename="package://fanuc_lrmate200id_support/meshes/lrmate200id7l/collision/link_2.stl" scale ="0.001 0.001 0.001"  />
		</geometry>
	</collision>
	<visual>
		<origin xyz="0 0 0" rpy="0 0 0"/>
		<geometry>
			<mesh filename = "package://fanuc_lrmate200id_support/meshes/lrmate200id7l/visual/link_2.stl"  scale ="0.001 0.001 0.001"/>
		</geometry>
	</visual>
	<inertial>
        <origin xyz="-0.002701 -0.000977 0.159466" rpy="0 0 0"/>
		<mass value = "1"/>
        <inertia
          ixx="${600 * 0.000182}" ixy="0.0" ixz="0.0"
          iyy="${600 * 0.000157}" iyz="${600 * -0.000001}"
          izz="${600 * 0.000049}"/>	</inertial>
</link>
<gazebo reference= "${prefix}link_2" >
	<material>Gazebo/Orange</material>
</gazebo>

<joint name="${prefix}joint_3" type="revolute">
      <origin xyz="0 0 0.440" rpy="0 0 0"/>
      <parent link="${prefix}link_2" />
      <child link="${prefix}link_3" />
      <axis xyz="0 -1 0" />
      <limit effort="0" lower="-2.450966" upper="4.886922" velocity="9.08" />
      <dynamics damping="1.0" friction="5.0"/>

</joint>

<link name="${prefix}link_3">
	<collision>
		<origin xyz="0 0 0" rpy="0 0 0"/>
		<geometry>
			<mesh filename="package://fanuc_lrmate200id_support/meshes/lrmate200id/collision/link_3.stl"/>
		</geometry>
	</collision>
	<visual>
		<origin xyz="0 0 0" rpy="0 0 0"/>
		<geometry>
			<mesh filename="package://fanuc_lrmate200id_support/meshes/lrmate200id/visual/link_3.stl"/>
		</geometry>
	</visual>
	<inertial>
        <origin xyz="-0.000065 0.017074 0.008866" rpy="0 0 0"/>
		<mass value = "1"/>
        <inertia
          ixx="${600 * 0.000007}" ixy="0.0" ixz="${600 * -0.000001}"
          iyy="${600 * 0.000008}" iyz="0.0"
          izz="${600 * 0.000008}"/>	</inertial>
</link>

<gazebo reference= "${prefix}link_3" >
	<material>Gazebo/Orange</material>
</gazebo>

<joint name="${prefix}joint_4" type="revolute">
      <origin xyz="0 0 0.035" rpy="0 0 0"/>
      <parent link="${prefix}link_3"/>
      <child link="${prefix}link_4"/>
      <axis xyz="-1 0 0"/>
      <limit effort="0" lower="-3.315" upper="3.315" velocity="9.60" />
      <dynamics damping="1.0" friction="5.0"/>

</joint>

<link name="${prefix}link_4">
	<collision>
		<origin xyz ="0 0 0" rpy = "0 0 0" />
		<geometry>
			<mesh filename="package://fanuc_lrmate200id_support/meshes/lrmate200id7l/collision/link_4.stl"  scale ="0.001 0.001 0.001"/>
		</geometry>
	</collision>
	<visual>
		<origin xyz ="0 0 0" rpy = "0 0 0" />
		<geometry>
			<mesh filename="package://fanuc_lrmate200id_support/meshes/lrmate200id7l/visual/link_4.stl" scale ="0.001 0.001 0.001"/>
		</geometry>
	</visual>
	<inertial>
        <origin xyz="0.000067 0.002203 0.221634" rpy="0 0 0"/>
		<mass value = "1"/>
        <inertia
          ixx="${600 * 0.000005}" ixy="0.0" ixz="0.0"
          iyy="${600 * 0.000019}" iyz="0.0"
          izz="${600 * 0.000019}"/>	</inertial>	

</link>

<gazebo reference= "${prefix}link_4" >
	<material>Gazebo/Orange</material>
</gazebo>

<joint name="${prefix}joint_5" type="revolute">
      <origin xyz="0.420 0 0" rpy="0 0 0"/>
      <parent link="${prefix}link_4"/>
      <child link="${prefix}link_5"/>
      <axis xyz="0 -1 0"/>
      <limit effort="0" lower="-2.18" upper="2.18" velocity="9.51" />
	  <dynamics damping="1.0" friction="5.0"/>

</joint>


<link name="${prefix}link_5">
	<collision>
		<origin xyz="0 0 0" rpy ="0 0 0"/>
		<geometry>
			<mesh filename="package://fanuc_lrmate200id_support/meshes/lrmate200id/collision/link_5.stl"/>
		</geometry>
	</collision>
	<visual>
		<origin xyz="0 0 0" rpy ="0 0 0"/>
		<geometry>
			<mesh filename="package://fanuc_lrmate200id_support/meshes/lrmate200id/visual/link_5.stl"/>
		</geometry>
	</visual>
	<inertial>
        <origin xyz="-0.000010 -0.054550 0.028725" rpy="0 0 0"/>
		<mass value = "1"/>
        <inertia
          ixx="${600 * 0.00004}" ixy="0.0" ixz="${600 * -0.000004}"
          iyy="${600 * 0.00003}" iyz="0.0" izz="${600 * 0.00003}"/>	</inertial>	

</link>

<gazebo reference= "${prefix}link_5" >
	<material>Gazebo/Orange</material>
</gazebo>

<joint name="${prefix}joint_6" type="revolute">
      <origin xyz="0.080 0 0" rpy="0 0 0"/>
      <parent link="${prefix}link_5"/>
      <child link="${prefix}link_6"/>
      <axis xyz="-1 0 0"/>
      <limit effort="0" lower="-6.285" upper="6.285" velocity="17.45" />
	  <dynamics damping="1.0" friction="5.0"/>

</joint>


<link name="${prefix}link_6">
	<collision>
		<origin xyz="0 0 0" rpy ="0 0 0"/>
		<geometry>
			<mesh filename="package://fanuc_lrmate200id_support/meshes/lrmate200id/collision/link_6.stl"/>
		</geometry>
	</collision>
	<visual>
		<origin xyz="0 0 0" rpy ="0 0 0"/>
		<geometry>
			<mesh filename="package://fanuc_lrmate200id_support/meshes/lrmate200id/visual/link_6.stl"/>
		</geometry>
	</visual>
	<inertial>
        <origin xyz="-0.000000 0.000000 -0.003006" rpy="0 0 0" />
		<mass value = "0.137"/>
        <inertia
          ixx="0.01" ixy="0.0" ixz="0.0"
          iyy="0.01" iyz="0.0"
          izz="0.01"/>	
	</inertial>	

</link>

<gazebo reference= "${prefix}link_6" >
	<material>Gazebo/Orange</material>
</gazebo>


    <!-- ROS-Industrial 'tool0' frame: all-zeros tool frame -->
<link name="${prefix}tool0" />
    <joint name="${prefix}link_6-tool0" type="fixed">
      <origin xyz="0 0 0" rpy="${pi} ${-pi/2.0} 0" />
      <parent link="${prefix}link_6" />
      <child link="${prefix}tool0" />
</joint>



<!--Transmission-->
 <transmission name="${prefix}tran1">
    <type>transmission_interface/SimpleTransmission</type>
    <joint name="${prefix}joint_1">
      <hardwareInterface>hardware_interface/PositionJointInterface</hardwareInterface>
    </joint>
    <actuator name="${prefix}joint_1_motor">
      <hardwareInterface>hardware_interface/PositionJointInterface</hardwareInterface>
      <mechanicalReduction>1</mechanicalReduction>
    </actuator>
  </transmission>

  <transmission name="${prefix}tran2">
    <type>transmission_interface/SimpleTransmission</type>
    <joint name="${prefix}joint_2">
      <hardwareInterface>hardware_interface/PositionJointInterface</hardwareInterface>
    </joint>
    <actuator name="${prefix}joint_2_motor">
      <hardwareInterface>hardware_interface/PositionJointInterface</hardwareInterface>
      <mechanicalReduction>1</mechanicalReduction>
    </actuator>
  </transmission>

 <transmission name="${prefix}tran3">
    <type>transmission_interface/SimpleTransmission</type>
    <joint name="${prefix}joint_3">
      <hardwareInterface>hardware_interface/PositionJointInterface</hardwareInterface>
    </joint>
    <actuator name="${prefix}joint_3_motor">
      <hardwareInterface>hardware_interface/PositionJointInterface</hardwareInterface>
      <mechanicalReduction>1</mechanicalReduction>
    </actuator>
  </transmission>
 <transmission name="${prefix}tran4">
    <type>transmission_interface/SimpleTransmission</type>
    <joint name="${prefix}joint_4">
      <hardwareInterface>hardware_interface/PositionJointInterface</hardwareInterface>
    </joint>
    <actuator name="${prefix}joint_4_motor">
      <hardwareInterface>hardware_interface/PositionJointInterface</hardwareInterface>
      <mechanicalReduction>1</mechanicalReduction>
    </actuator>
  </transmission>
 <transmission name="${prefix}tran5">
    <type>transmission_interface/SimpleTransmission</type>
    <joint name="${prefix}joint_5">
      <hardwareInterface>hardware_interface/PositionJointInterface</hardwareInterface>
    </joint>
    <actuator name="${prefix}joint_5_motor">
      <hardwareInterface>hardware_interface/PositionJointInterface</hardwareInterface>
      <mechanicalReduction>1</mechanicalReduction>
    </actuator>
  </transmission>

   <transmission name="${prefix}tran6">
    <type>transmission_interface/SimpleTransmission</type>
    <joint name="${prefix}joint_6">
      <hardwareInterface>hardware_interface/PositionJointInterface</hardwareInterface>
    </joint>
    <actuator name="${prefix}joint_6_motor">
      <hardwareInterface>hardware_interface/PositionJointInterface</hardwareInterface>
      <mechanicalReduction>1</mechanicalReduction>
    </actuator>
  </transmission>
    
	
  </xacro:macro>

</robot>