<?xml version="1.0"?>
<robot xmlns:xacro="http://www.ros.org/wiki/xacro">
  <xacro:include filename="$(find fanuc_lrmate200id_support)/urdf/common_materials.xacro"/>

  <xacro:macro name="fanuc_lrmate200id7l" params="prefix">
    <!-- links: main serial chain -->
    <link name="${prefix}base_link">
      <visual>
        <origin xyz="0 0 0" rpy="0 0 0"/>
        <geometry>
          <mesh filename="package://fanuc_lrmate200id_support/meshes/lrmate200id/visual/base_link.stl"/>
        </geometry>
        <xacro:material_fanuc_gray28 />
      </visual>
      <collision>
        <origin xyz="0 0 0" rpy="0 0 0"/>
        <geometry>
          <mesh filename="package://fanuc_lrmate200id_support/meshes/lrmate200id/collision/base_link.stl"/>
        </geometry>
      </collision>
      <inertial>
          <mass value="10.733459"/>
          <origin xyz="0.014288 0.000001 0.122264" rpy="0.0 0.0 0.0"/>
          <inertia ixx="0.096590" ixy="-0.000005" ixz="-0.003803"
                                  iyy="0.087591"  iyz="-0.000001"
                                                  izz="0.081632"/>
      </inertial>
    </link>
    <link name="${prefix}link_1">
      <visual>
        <origin xyz="0 0 0" rpy="0 0 0"/>
        <geometry>
          <mesh filename="package://fanuc_lrmate200id_support/meshes/lrmate200id/visual/link_1.stl"/>
        </geometry>
        <xacro:material_fanuc_yellow />
      </visual>
      <collision>
        <origin xyz="0 0 0" rpy="0 0 0"/>
        <geometry>
          <mesh filename="package://fanuc_lrmate200id_support/meshes/lrmate200id/collision/link_1.stl"/>
        </geometry>
      </collision>
      <inertial>
          <mass value="16.934564"/>
          <origin xyz="0.019143 0.024764 -0.064596" rpy="0.0 0.0 0.0"/>
          <inertia ixx="0.222318" ixy="0.016499" ixz="0.023794"
                                  iyy="0.208959" iyz="0.031663"
                                                 izz="0.157081"/>
      </inertial>
    </link>
    <link name="${prefix}link_2">
      <visual>
        <origin xyz="0 0 0" rpy="0 0 0"/>
        <geometry>
          <mesh filename="package://fanuc_lrmate200id_support/meshes/lrmate200id7l/visual/link_2.stl" scale="0.001 0.001 0.001"/>
        </geometry>
        <xacro:material_fanuc_yellow />
      </visual>
      <collision>
        <origin xyz="0 0 0" rpy="0 0 0"/>
        <geometry>
          <mesh filename="package://fanuc_lrmate200id_support/meshes/lrmate200id7l/collision/link_2.stl" scale="0.001 0.001 0.001"/>
        </geometry>
      </collision>
      <inertial>
          <mass value="12.98711"/>
          <origin xyz="-0.000008 0.221181 0.173052" rpy="0.0 0.0 0.0"/>
          <inertia ixx="0.425299" ixy="0.000005" ixz="-0.000004"
                                  iyy="0.452311" iyz="-0.002920"
                                                 izz="0.054493"/>
      </inertial>
    </link>
    <link name="${prefix}link_3">
      <visual>
        <origin xyz="0 0 0" rpy="0 0 0"/>
        <geometry>
          <mesh filename="package://fanuc_lrmate200id_support/meshes/lrmate200id/visual/link_3.stl"/>
        </geometry>
        <xacro:material_fanuc_yellow />
      </visual>
      <collision>
        <origin xyz="0 0 0" rpy="0 0 0"/>
        <geometry>
          <mesh filename="package://fanuc_lrmate200id_support/meshes/lrmate200id/collision/link_3.stl"/>
        </geometry>
      </collision>
      <inertial>
          <mass value="7.50151"/>
          <origin xyz="0.000002 0.065008 0.003572" rpy="0.0 0.0 0.0"/>
          <inertia ixx="0.058902" ixy="0.000000" ixz="0.000001"
                                  iyy="0.056884" iyz="-0.003672"
                                                 izz="0.034271"/>
      </inertial>
    </link>
    <link name="${prefix}link_4">
      <visual>
        <origin xyz="0 0 0" rpy="0 0 0"/>
        <geometry>
          <mesh filename="package://fanuc_lrmate200id_support/meshes/lrmate200id7l/visual/link_4.stl" scale="0.001 0.001 0.001"/>
        </geometry>
        <xacro:material_fanuc_yellow />
      </visual>
      <collision>
        <origin xyz="0 0 0" rpy="0 0 0"/>
        <geometry>
          <mesh filename="package://fanuc_lrmate200id_support/meshes/lrmate200id7l/collision/link_4.stl" scale="0.001 0.001 0.001"/>
        </geometry>
      </collision>
      <inertial>
          <mass value="4.54015"/>
          <origin xyz="-0.002488 0.049988 0.296156" rpy="0.0 0.0 0.0"/>
          <inertia ixx="0.043246" ixy="0.000003" ixz="-0.000683"
                                  iyy="0.038394" iyz="-0.000004"
                                                 izz="0.014525"/>
      </inertial>
    </link>
    <link name="${prefix}link_5">
      <visual>
        <origin xyz="0 0 0" rpy="0 0 0"/>
        <geometry>
          <mesh filename="package://fanuc_lrmate200id_support/meshes/lrmate200id/visual/link_5.stl"/>
        </geometry>
        <xacro:material_fanuc_yellow />
      </visual>
      <collision>
        <origin xyz="0 0 0" rpy="0 0 0"/>
        <geometry>
          <mesh filename="package://fanuc_lrmate200id_support/meshes/lrmate200id/collision/link_5.stl"/>
        </geometry>
      </collision>
      <inertial>
          <mass value="0.56876"/>
          <origin xyz="0.000000 0.049931 0.222823" rpy="0.0 0.0 0.0"/>
          <inertia ixx="0.001084" ixy="0.000000" ixz="0.000000"
                                  iyy="0.001123" iyz="0.000001"
                                                 izz="0.000383"/>
      </inertial>
    </link>
    <link name="${prefix}link_6">
      <visual>
        <origin xyz="0 0 0" rpy="0 0 0"/>
        <geometry>
          <mesh filename="package://fanuc_lrmate200id_support/meshes/lrmate200id/visual/link_6.stl"/>
        </geometry>
        <xacro:material_fanuc_black />
      </visual>
      <collision>
        <origin xyz="0 0 0" rpy="0 0 0"/>
        <geometry>
          <mesh filename="package://fanuc_lrmate200id_support/meshes/lrmate200id/collision/link_6.stl"/>
        </geometry>
      </collision>
      <inertial>
          <mass value="0.03098"/>
          <origin xyz="-0.000243 0.050000 -0.006293" rpy="0.0 0.0 0.0"/>
          <inertia ixx="0.000012" ixy="0.000000" ixz="0.000000"
                                  iyy="0.000011" iyz="0.000000"
                                                 izz="0.000022"/>
      </inertial>
    </link>

    <!-- joints: main serial chain -->
    <joint name="${prefix}joint_1" type="revolute">
      <origin xyz="0 0 0.330" rpy="0 0 0" />
      <parent link="${prefix}base_link" />
      <child link="${prefix}link_1" />
      <axis xyz="0 0 1" />
      <limit effort="0" lower="-2.965" upper="2.965" velocity="7.85" />
    </joint>
    <joint name="${prefix}joint_2" type="revolute">
      <origin xyz="0.050 0 0" rpy="0 0 0"/>
      <parent link="${prefix}link_1" />
      <child link="${prefix}link_2" />
      <axis xyz="0 1 0" />
      <limit effort="0" lower="-1.745329" upper="2.530727" velocity="6.63" />
    </joint>
    <joint name="${prefix}joint_3" type="revolute">
      <origin xyz="0 0 0.440" rpy="0 0 0"/>
      <parent link="${prefix}link_2" />
      <child link="${prefix}link_3" />
      <axis xyz="0 -1 0" />
      <limit effort="0" lower="-2.450966" upper="4.886922" velocity="9.08" />
    </joint>
    <joint name="${prefix}joint_4" type="revolute">
      <origin xyz="0 0 0.035" rpy="0 0 0"/>
      <parent link="${prefix}link_3"/>
      <child link="${prefix}link_4"/>
      <axis xyz="-1 0 0"/>
      <limit effort="0" lower="-3.315" upper="3.315" velocity="9.60" />
    </joint>
    <joint name="${prefix}joint_5" type="revolute">
      <origin xyz="0.420 0 0" rpy="0 0 0"/>
      <parent link="${prefix}link_4"/>
      <child link="${prefix}link_5"/>
      <axis xyz="0 -1 0"/>
      <limit effort="0" lower="-2.18" upper="2.18" velocity="9.51" />
    </joint>
    <joint name="${prefix}joint_6" type="revolute">
      <origin xyz="0.080 0 0" rpy="0 0 0"/>
      <parent link="${prefix}link_5"/>
      <child link="${prefix}link_6"/>
      <axis xyz="-1 0 0"/>
      <limit effort="0" lower="-6.285" upper="6.285" velocity="17.45" />
    </joint>

    <!-- ROS-Industrial 'base' frame: base_link to Fanuc World Coordinates transform -->
    <link name="${prefix}base" />
    <joint name="${prefix}base_link-base" type="fixed">
      <origin xyz="0 0 0.330" rpy="0 0 0"/>
      <parent link="${prefix}base_link"/>
      <child link="${prefix}base"/>
    </joint>

    <!-- ROS-Industrial 'flange' frame: attachment point for EEF models -->
    <link name="${prefix}flange" />
    <joint name="${prefix}joint_6-flange" type="fixed">
      <origin xyz="0 0 0" rpy="0 0 0" />
      <parent link="${prefix}link_6" />
      <child link="${prefix}flange" />
    </joint>

    <link name="${prefix}tool0">
      <visual>
        <origin xyz="0 0 0" rpy="0 0 0"/>
        <geometry>
          <mesh filename="package://fanuc_lrmate200id_support/meshes/lrmate200id/visual/link_6.stl"/>
        </geometry>
        <xacro:material_fanuc_black />
      </visual>
      <collision>
        <origin xyz="0 0 0" rpy="0 0 0"/>
        <geometry>
          <mesh filename="package://fanuc_lrmate200id_support/meshes/lrmate200id/collision/link_6.stl"/>
        </geometry>
      </collision>
    </link>



    <joint name="${prefix}link_6-tool0" type="fixed">
      <origin xyz="0 0 0" rpy="${pi} ${-pi/2.0} 0" />
      <parent link="${prefix}link_6" />
      <child link="${prefix}tool0" />
    </joint>
  </xacro:macro>
</robot>